Workbook
Name _Toc56965787: Introduction!$A$1
Name _Toc56965787: 'Overall Description'!$A$1

Sheet Cover

Sheet Table of Contents
E4: Table of Contents
D6: 1 | E6: Introduction
D7: 2 | E7: Overall Description
D8: 3 | E8: Testing Approach Strategy'
D9: 4 | E9: 'Unit Testing Summary'!A1
D10: 5 | E10: 'Test Case Details'!A1

Sheet Introduction
A1: 1. Introduction
A2: 1.1. Objective
A3: This Unit Testing Plan document was prepared for AIMS Group 23 to define the objectives, scope, and testing strategy for the Unit Testing phase of the project. This document is intended for developers to ensure the accuracy of individual software components such as product management functions, shipping cost calculation, and payment integration (PayPal, VietQR). This document will be developed in parallel with the project's source code.
A13: 1.2 Scope
A14: Our project focuses on developing the AIMS product management and e-commerce system. The scope of this Unit Test Plan covers our core modules: - Product Management (adding, editing, deleting, and adjusting inventory) - Order Processing (creating orders and calculating shipping fees) - Payment Integration through PayPal Sandbox and VietQR. This phase excludes actual database or UI integration testing, as we will be using mocks. Our primary goal is to detect bugs early and ensure the business logic is entirely accurate.
A26: 1.3. Glossary
A27: - UT (Unit Testcase): Testing of the smallest testable parts of an application. - UC (Use Case): A description of a system's behavior as it responds to a request from a user. - TDD (Test-Driven Development): A software development process relying on software requirements being converted to test cases before software is fully developed. - Mock: Simulated objects that mimic the behavior of real objects in controlled ways to isolate the unit under test. - Traceability Matrix: A document that co-relates test cases to functional requirements.
A35: 1.4. References
A36: - Jest Documentation. Retrieved from: https://jestjs.io/ - NGUYEN Thi Thu Trang. AIMS: An Internet Media Store - CAPSTONE-PROJECT PROBLEM STATEMENT - NGUYEN Thi Thu Trang. Lab 10: Unit Testing - ITSS SOFTWARE DEVELOPMENT. SOICT - HUST

Sheet Overall Description
A1: 2. Overall Description
A2: 2.1. General Overview
A3: AIMS is an e-commerce platform for purchasing physical media, providing a seamless shopping experience for customers and inventory control tools for managers.Regarding its development history, the project has completed the SRS and SDD phases and is currently in the implementation phase, utilizing Test-Driven Development (TDD) to verify core business logic.High-level diagrams (Use Case, Activity, and Package diagrams) remain as defined in the previous SRS and SDD documents. However, the Sequence Diagrams have been updated. Specifically, a new external actor (lifeline) was added to represent the third-party payment service (PayPal Sandbox). This change was made to accurately reflect the independent communication with external payment gateways and to establish a solid basis for mocking the payment module during this Unit Testing phase.
A14: 2.2. Assumptions/Constraints/Risks
A15: 2.2.1. Assumptions
A16: Development Process: The team strictly follow Test-Driven Development (TDD) strategy, consistently following the Red-Green-Refactor cycle. Input Data: The product specifications (Books, CDs, DVDs, and Newspapers) and shipping fee calculation rules (for Hanoi, HCMC, and other provinces) detailed in the Problem Statement are accurate and will remain unchanged throughout the unit testing phase. Mock Environment: We do test under the assumption that all external dependencies, such as the database and third-party APIs (PayPal, VietQR), can be fully substituted with mocks or stubs. This guarantees the independence of our unit tests. Tools: Jest has been successfully intergrated into the project.
A22: 2.2.2. Constraints
A23: - Testing Technique: We must utilize Black-box testing, focusing strictly on input and output based on business requirements, without interfering with the internal source code structure. - Unit Scope: Unit tests will exclusively target individual modules and methods (such as validateDeliveryInfo and calculateShippingFee). They should not be used to test complex user interfaces or interactions between large subsystems. - Language & Framework: We will be using Jest for this project. - Directory Structure: When submitting code to GitHub, the required directory structure must be strictly followed, ensuring that the test directory is located within the api folder (e.g., api/test).
A36: 2.2.3. Risks
A37: Business Logic Risks: The complexity of our shipping fee rules (such as a maximum 25k VND discount for orders exceeding 100k VND, and weight-based pricing at 0.5kg or 3kg) increases the risk of missing boundary values.Solution: Design test cases that specifically target these threshold points (100,000 VND, 3kg, and 0.5kg). Mock Integration Risks: Mocking our payment gateways (PayPal/VietQR) may not perfectly replicate the actual response logic of the Sandbox environment. Solution: Carefully review the official API documentation and implement additional test cases dedicated to handling exceptions and error codes. Maintenance Risks: Rapid changes to the source code can cause older unit tests to fail (Regression). Solution: Enforce running the entire test suite after every code refactor.

Sheet Testing Approach Strategy
A1: 3. Testing Approach/Strategy
A2: 3.1. Overview - Unit Testing Strategy: Our approach focuses on verifying the individual components of the AIMS application, such as services, controllers, and functions. - Testing Technique: We are exclusively applying a Black-box testing strategy for this project. Test cases are designed solely around the functional requirements and expected behaviors outlined in the problem statement, without examining the internal source code. This approach ensures that the system accurately fulfills the business logic and user needs. - Dependency Isolation: All external dependencies, including the database and APIs, will be strictly isolated using Mocks and Stubs via Jest. 3.2. Scope of Unit Testing Unit Testing Scope: The scope encompasses the functions, methods, services, and controllers responsible for the core business logic of the AIMS system. In-Scope Components: - Product Management: - Product.validatePrice: Validating the 30% - 150% base price constraints. - ProductController.delete: Ensuring products are only deleted when out of stock, and enforcing limits (10 items per bulk action, 20 items daily quota). - Product.adjustStock: Validating manual stock updates (requiring a reason, ensuring inputs are non-negative integers). - ProductDetailMapper: Mapping detailed attributes for specific categories (Books, Newspapers, CDs, DVDs). - Order & Delivery: - DeliveryInfoValidator: Validating receiver names (letters only), phone numbers (10 digits with separator handling), and capping addresses/delivery instructions at 200 characters. - ShippingFeeService.calculateShippingFee: Testing region-based logic (Hanoi/HCMC vs. other provinces), weight tiers (0.5kg/3kg), and shipping discounts (max 25k free for orders > 100k). - Payment Integration: - createOrder, capturePayment, refundPayment: Handling PayPal Sandbox API flows, including decimal formatting and error handling for tokens/APIs. - VietqrService: Testing Access Token retrieval, QR code generation, and Callback logic (digital signature validation, amount matching, and duplicate transaction prevention). - rejectPaidVietQROrder: Handling manual refund notifications for rejected VietQR orders. - Product Services: - ProductDetailService & ProductAvailabilityService: Verifying product detail viewing permissions, product ID validation, and stock statuses (Available, Out of stock, Unavailable). - CartQuantityValidator: Ensuring cart additions do not exceed actual inventory. Out-of-Scope Components: - End-to-end (E2E) UI testing. - Direct interactions with the actual database (to be replaced entirely by Mocks/Stubs). - Real network connections to PayPal/VietQR payment gateways (utilizing Sandbox environments and Mock Axios instead). - Full system workflow testing across multiple integrated modules.
A21: 3.3. Strategy for Designing Unit Tests Our test cases are designed entirely using the following Black-box techniques: - Equivalence Partitioning: We categorize input data into valid and invalid groups to ensure comprehensive coverage (for example, validating phone number formats or checking for positive versus negative product quantities). - Boundary Value Analysis: We focus heavily on critical thresholds, such as the 100,000 VND order mark, the 0.5kg and 3kg weight tiers, and product pricing limits (ranging from 30% to 150% of the original price). - Decision Tables: We apply this method to handle complex business logic, such as determining whether to approve or reject an order based on a combination of inventory levels and payment status. 3.4. Tools and Frameworks JEST: Used as the primary testing framework to automate unit tests. Mocking: Utilized Jest's mocking features to isolate modules from external dependencies.

Sheet Unit Testing Summary
A1: 4. Unit Testing Summary
A2: 4.1. Traceability from Test Cases to Use Cases
A3: <Mark the cell with an "x" where the Test Case tests.>
A4: USE CASE ID | D4: UC234.1 Add Product | E4: UC234.2 Edit Product | F4: UC234.3 Adjust Quantity | G4: UC234.4 Delete Product | H4: UC233 Pay by Credit Card | I4: UC232 Pay by VietQR | J4: UC235 View Product Detail | K4: UC231 Place Order
A5: Test Case ID | B5: Test CaseTitle | C5: Totals | D5: =COUNTIF(D6:D21,"=x") -> 8 | E5: =COUNTIF(E6:E21,"=x") -> 8 | F5: =COUNTIF(F6:F21,"=x") -> 4 | G5: =COUNTIF(G6:G21,"=x") -> 4 | H5: =COUNTIF(H6:H1076,"=x") -> 13 | I5: 10 | J5: 19 | K5: =COUNTIF(K6:K78,"=x") -> 16
A6: UT_PM_001 | B6: validatePrice - Price at lower bound (30%) | C6: =COUNTIF(D6:K6,"=x") -> 2 | D6: x | E6: x
A7: UT_PM_002 | B7: validatePrice - Price below minimum bound | C7: =COUNTIF(D7:K7,"=x") -> 2 | D7: x | E7: x
A8: UT_PM_003 | B8: validatePrice - Price at upper bound (150%) | C8: =COUNTIF(D8:K8,"=x") -> 2 | D8: x | E8: x
A9: UT_PM_004 | B9: validatePrice - Price exceeds maximum bound | C9: =COUNTIF(D9:K9,"=x") -> 2 | D9: x | E9: x
A10: UT_PM_005 | B10: validatePrice - Price is zero or negative | C10: =COUNTIF(D10:K10,"=x") -> 2 | D10: x | E10: x
A11: UT_PM_006 | B11: validatePrice - Valid price level (Middle) | C11: =COUNTIF(D11:K11,"=x") -> 2 | D11: x | E11: x
A12: UT_PM_007 | B12: validatePrice - Price data is non-numeric | C12: =COUNTIF(D12:K12,"=x") -> 2 | D12: x | E12: x
A13: UT_PM_008 | B13: deleteProduct - Delete product when stock = 0 | C13: =COUNTIF(D13:K13,"=x") -> 1 | G13: x
A14: UT_PM_009 | B14: deleteProduct - Delete product while in stock | C14: =COUNTIF(D14:K14,"=x") -> 1 | G14: x
A15: UT_PM_010 | B15: deleteProduct - Bulk delete exceeds limit | C15: =COUNTIF(D15:K15,"=x") -> 1 | G15: x
A16: UT_PM_011 | B16: deleteProduct - Exceeds daily deletion limit | C16: =COUNTIF(D16:K16,"=x") -> 1 | G16: x
A17: UT_PM_012 | B17: adjustStock - Update stock with reason | C17: =COUNTIF(D17:K17,"=x") -> 1 | F17: x
A18: UT_PM_013 | B18: adjustStock - Update stock without reason | C18: =COUNTIF(D18:K18,"=x") -> 1 | F18: x
A19: UT_PM_014 | B19: adjustStock - Decrease stock causing negative quantity | C19: =COUNTIF(D19:K19,"=x") -> 1 | F19: x
A20: UT_PM_015 | B20: adjustStock - Adjustment quantity is non-integer | C20: =COUNTIF(D20:K20,"=x") -> 1 | F20: x
A21: UT_PM_016 | B21: validateBook - Validate Book information (Author, Publisher) | C21: =COUNTIF(D21:K21,"=x") -> 2 | D21: x | E21: x
A22: UT_PM_017 | B22: validateDVD - Validate DVD information (Director, Studio) | C22: =COUNTIF(D22:K22,"=x") -> 2 | D22: x | E22: x
A23: UT_ORD_001 | B23: createOrder - Successfully calls API with valid amount | C23: =COUNTIF(D24:K24,"=x") -> 1 | H23: x
A24: UT_ORD_002 | B24: createOrder - Handles decimal formatting (toFixed) | C24: =COUNTIF(D24:K24,"=x") -> 1 | H24: x
A25: UT_ORD_003 | B25: createOrder - Handles error when getAccessToken fails | C25: =COUNTIF(D25:K25,"=x") -> 1 | H25: x
A26: UT_ORD_004 | B26: createOrder - Handles API error responses (400/500) | C26: =COUNTIF(D26:K26,"=x") -> 1 | H26: x
A27: UT_PAY_001 | B27: capturePayment - Valid transaction | C27: =COUNTIF(D27:K27,"=x") -> 1 | H27: x
A28: UT_PAY_002 | B28: capturePayment - Insufficient card balance | C28: =COUNTIF(D28:K28,"=x") -> 1 | H28: x
A29: UT_PAY_003 | B29: capturePayment - Duplicate payment | C29: =COUNTIF(D29:K29,"=x") -> 1 | H29: x
A30: UT_REF_001 | B30: refundPayment - Full refund | C30: =COUNTIF(D30:K30,"=x") -> 1 | H30: x
A31: UT_REF_002 | B31: refundPayment - Valid partial refund | C31: =COUNTIF(D31:K31,"=x") -> 1 | H31: x
A32: UT_REF_003 | B32: refundPayment - Refund exceeds captured amount | C32: =COUNTIF(D32:K32,"=x") -> 1 | H32: x
A33: UT_REF_004 | B33: refundPayment - Refund for unpaid order | C33: =COUNTIF(D33:K33,"=x") -> 1 | H33: x
A34: UT_VQR_001 | B34: Get access token successfully | C34: 1 | H34: x | I34: x
A35: UT_VQR_002 | B35: Get access token failed | C35: 1 | H35: x | I35: x
A36: UT_VQR_003 | B36: Generate QR code successfully | C36: 1 | I36: x
A37: UT_VQR_004 | B37: Generate QR code failed due to VietQR API error | C37: 1 | I37: x
A38: UT_VQR_005 | B38: Generate QR code failed due to invalid amount | C38: 1 | I38: x
A39: UT_VQR_006 | B39: Handle valid payment callback successfully | C39: 1 | I39: x
A40: UT_VQR_007 | B40: Reject callback with invalid signature | C40: 1 | I40: x
...

Sheet Test Case Details
A1: 5. Test Case Details
A2: Test Case ID | B2: Test Case Name | C2: Description | D2: Unit Under Test | E2: Input Data | F2: Expected Output | G2: Actual Output | H2: Pass/Fail | I2: Notes
A3: ='Unit Testing Summary'!A6 -> UT_PM_001 | B3: Validate Lower Price | C3: Check price at the 30% minimum limit | D3: `Product.validatePrice(orig, curr)` | E3: `orig=200.000`, `curr=60.000` | F3: `TRUE` | G3: TRUE | H3: pass
A4: ='Unit Testing Summary'!A7 -> UT_PM_002 | B4: Test Price Below Min | C4: Check price below the 30% limit | D4: `Product.validatePrice(orig, curr)` | E4: `orig=200.000`, `curr=59.000` | F4: `FALSE` | G4: FALSE | H4: pass
A5: ='Unit Testing Summary'!A8 -> UT_PM_003 | B5: Validate Upper Price | C5: Check price at the 150% maximum limit | D5: `Product.validatePrice(orig, curr)` | E5: `orig=100.000`, `curr=150.000` | F5: `TRUE` | G5: TRUE | H5: pass
A6: ='Unit Testing Summary'!A9 -> UT_PM_004 | B6: Test Price Above Max | C6: Check price exceeding the 150% limit | D6: `Product.validatePrice(orig, curr)` | E6: `orig=100.000`, `curr=150.100` | F6: `FALSE` | G6: FALSE | H6: pass
A7: ='Unit Testing Summary'!A10 -> UT_PM_005 | B7: Price Invalid Input | C7: Enter selling price as 0 or negative | D7: `Product.validatePrice(orig, curr)` | E7: `curr=-10.000` | F7: `FALSE` (Invalid Price) | G7: FALSE | H7: pass
A8: ='Unit Testing Summary'!A11 -> UT_PM_006 | B8: Price Middle Valid | C8: Check price within the allowed range | D8: `Product.validatePrice(orig, curr)` | E8: `orig=100.000`, `curr=80.000` | F8: `TRUE` | G8: TRUE | H8: pass
A9: ='Unit Testing Summary'!A12 -> UT_PM_007 | B9: Price Type Mismatch | C9: Enter alphabetic characters into the price field | D9: `Product.validatePrice(orig, curr)` | E9: `curr="abc"` | F9: `FALSE` (Numeric Required) | G9: FALSE | H9: pass
A10: ='Unit Testing Summary'!A13 -> UT_PM_008 | B10: Delete with Zero Stock | C10: Delete product when out of stock | D10: `ProductController.delete(product)` | E10: `stock=0` | F10: `Status: DELETED` | G10: { status: 'DELETED' } | H10: pass
A11: ='Unit Testing Summary'!A14 -> UT_PM_009 | B11: Delete with In-Stock | C11: Delete product while still in stock | D11: `ProductController.delete(product)` | E11: `stock=10` | F11: `Status: DEACTIVATED` | G11: { status: 'DEACTIVATED' } | H11: pass
A12: ='Unit Testing Summary'!A15 -> UT_PM_010 | B12: Bulk Delete Limit | C12: Check single deletion limit | D12: `ProductController.delete(list)` | E12: `List size = 11` | F12: `Throw Exception` | G12: Throw BadRequestException | H12: pass
A13: ='Unit Testing Summary'!A16 -> UT_PM_011 | B13: Daily Delete Quota | C13: Check daily deletion limit | D13: `ProductController.delete(product)` | E13: `21st delete in day` | F13: `Throw Exception` | G13: Throw HttpException | H13: pass
A14: ='Unit Testing Summary'!A17 -> UT_PM_012 | B14: Stock Update Reason | C14: Update inventory with a reason | D14: `Product.adjustStock(qty, reason)` | E14: `qty=-5`, `reason="Hỏng"` | F14: `TRUE` (Updated) | G14: TRUE | H14: pass
A15: ='Unit Testing Summary'!A18 -> UT_PM_013 | B15: Missing Stock Reason | C15: Update inventory without a reason | D15: `Product.adjustStock(qty, reason)` | E15: `qty=10`, `reason=""` | F15: `FALSE` (Error) | G15: FALSE | H15: pass
A16: ='Unit Testing Summary'!A19 -> UT_PM_014 | B16: Negative Stock Result | C16: Decrease inventory resulting in negative stock | D16: `Product.adjustStock(qty, reason)` | E16: `curr=5`, `adj=-10` | F16: `FALSE` (Stock \>= 0) | G16: FALSE | H16: pass
A17: ='Unit Testing Summary'!A20 -> UT_PM_015 | B17: Stock Non-Integer | C17: Enter inventory quantity as a decimal | D17: `Product.adjustStock(qty, reason)` | E17: `qty=1.5` | F17: `FALSE` (Integer required) | G17: FALSE | H17: pass
A18: ='Unit Testing Summary'!A21 -> UT_PM_016 | B18: Validate Book Info | C18: Check book information | D18: `Book.validate()` | E18: `Type:Book`, `Author:null` | F18: `FALSE` | G18: FALSE | H18: pass
A19: ='Unit Testing Summary'!A22 -> UT_PM_017 | B19: Validate DVD Info | C19: Check DVD information | D19: `DVD.validate()` | E19: `Type:DVD`, `Director:null` | F19: `FALSE` | G19: FALSE | H19: pass
A20: UT_ORD_001 | B20: createOrder - Valid API call | C20: Verify successful API call to PayPal Sandbox returns order data | D20: createOrder(amount) | E20: amount=100.00 Mock Axios: status: 201, data: { id: "ORD123" } | F20: Return { id: "ORD123" } | G20: Return { id: "ORD123" } | H20: pass | I20: Valid conditions met
A21: UT_ORD_002 | B21: createOrder - Decimal formatting | C21: Ensure the amount is automatically formatted to exactly 2 decimal places | D21: createOrder(amount) | E21: amount=99.9 | F21: Axios called with payload value: "99.90" | G21: value: "99.90" | H21: pass | I21: Validates toFixed(2) logic
A22: UT_ORD_003 | B22: createOrder - Auth token failure | C22: Handle error execution flow when retrieving Access Token fails | D22: createOrder(amount) | E22: amount=50.00 Mock getAccessToken: Throw Error | F22: Throw Error Axios post not called | G22: Throw Error Error: "Failed to get access token" | H22: pass | I22: Auth layer protection
A23: UT_ORD_004 | B23: createOrder - API rejection | C23: Handle 4xx/5xx errors returned from PayPal Order API | D23: createOrder(amount) | E23: amount=150.00 Mock Axios: Throw AxiosError(400) | F23: Throw Error containing Axios response details | G23: Throw Error | H23: pass | I23: Ensures catch block works
A24: UT_PAY_001 | B24: capturePayment - Valid capture | C24: Verify successful payment capture API call updates transaction | D24: capturePayment(orderId) | E24: orderId="ORD123" Mock Axios: status: 201, data: { status: "COMPLETED" } | F24: Return { status: "COMPLETED" } | G24: Return { status: "COMPLETED" } | H24: pass | I24: Valid conditions met
A25: UT_PAY_002 | B25: capturePayment - Capture declined | C25: Handle payment declined by external payment gateway | D25: capturePayment(orderId) | E25: orderId="ORD123" Mock Axios: Throw AxiosError(422) | F25: Throw Error with failure reason | G25: Throw Error | H25: pass | I25: Gateway rejection handling
A26: UT_PAY_003 | B26: capturePayment - Already captured | C26: Handle error when capturing an order state that is already paid | D26: capturePayment(orderId) | E26: orderId="ORD_PAID" Mock Axios: Throw AxiosError(400) | F26: Throw Error preventing duplicate charge | G26: Throw Error | H26: pass | I26: Prevent double charging
A27: UT_REF_001 | B27: refundPayment - Full refund | C27: Verify successful full refund API call execution | D27: refundPayment(captureId, amount) | E27: captureId="CAP123", amount=100.00 Mock Axios: status: 201 | F27: Return { status: "COMPLETED" } | G27: Return { status: "COMPLETED" } | H27: pass | I27: Valid conditions met
A28: UT_REF_002 | B28: refundPayment - Partial refund | C28: Verify successful partial refund API call execution | D28: refundPayment(captureId, amount) | E28: captureId="CAP123", amount=50.00 Mock Axios: status: 201 | F28: Return { status: "COMPLETED" } | G28: Return { status: "COMPLETED" } | H28: pass | I28: Tests payload logic
A29: UT_REF_003 | B29: refundPayment - Exceed amount | C29: Handle refund amount exceeding the initially captured amount | D29: refundPayment(captureId, amount) | E29: amount=200.00 (exceeds captured) Mock Axios: Throw AxiosError(422) | F29: Throw Error | G29: Throw Error | H29: pass | I29: Sandbox rejects over-refund
A30: UT_REF_004 | B30: refundPayment - Unsettled transaction | C30: Handle error when trying to refund a transaction not yet settled | D30: refundPayment(captureId, amount) | E30: captureId="CAP123" Mock Axios: Throw AxiosError(400) | F30: Throw Error indicating invalid status | G30: Throw Error | H30: pass | I30: Timing edge case handling
A31: UT_PO_001 | B31: validateReceiverName - Reject blank receiver name | C31: Verify that receiver name is mandatory and cannot be blank. | D31: DeliveryInfoValidator.validateReceiverName(receiverName) | E31: receiverName = '' | F31: Return validation error: Receiver name is required. | G31: Validation error returned: Receiver name is required. | H31: Pass | I31: Negative case for required delivery field.
... A56: UT_VQR_010 | B56: rejectPaidVietQROrder - Notify manual refund required | C56: Verify that the system notifies Product Manager to refund manually when a paid VietQR order is rejected. | D56: PaymentService.rejectPaidVietQROrder(orderId, rejectReason) / OrderService.rejectOrder(orderId, rejectReason) | E56: orderId="ORDER001"; paymentMethod="VIETQR"; orderStatus="PAID"; rejectReason="Out of stock". | F56: Notify Product Manager that manual refund is required; do not trigger automatic refund API. | G56: Notify Product Manager that manual refund is required and do not trigger automatic refund API. | H56: pass | I56: VietQR does not support automatic refund in current scope.
A57: UT_VPD_001 | B57: validateProductId - Accept Valid ID | C57: Verify that a valid product identifier is accepted before retrieving product detail. | D57: ProductDetailValidator.validateProductId(productId) | E57: productId = 'BK10293847' | F57: Return TRUE / valid product id. | G57: TRUE | H57: pass | I57: Covers valid partition: non-empty alphanumeric barcode/product id.
A58: UT_VPD_002 | B58: validateProductId - Reject Blank ID | C58: Verify that blank or null product identifier is rejected. | D58: ProductDetailValidator.validateProductId(productId) | E58: productId = null; productId = '' | F58: Return FALSE or validation error: Product id is required. | G58: FALSE | H58: pass | I58: Covers boundary/invalid partition: null and empty string.
A59: UT_VPD_003 | B59: validateProductId - Reject Invalid Format | C59: Verify that product identifier with unsupported characters is rejected. | D59: ProductDetailValidator.validateProductId(productId) | E59: productId = '../bad-id' or 'BK 1029@3847' | F59: Return FALSE or validation error: Product id format is invalid. | G59: FALSE | H59: pass | I59: Black-box test for invalid format input.
A60: UT_VPD_004 | B60: findProductById - Product Exists | C60: Verify that the method returns product detail data when the selected product exists in catalog. | D60: ProductDetailService.findProductById(productId) | E60: productId = 'BK10293847'; mocked repository returns product object | F60: Return product object/detail DTO containing product name, type, barcode, price, description, weight, and dimensions. | G60: Return product detail DTO with product name, type, barcode, price, description, weight and dimensions. | H60: pass | I60: Covers main flow: selected product exists.
A61: UT_VPD_005 | B61: findProductById - Product Not Found | C61: Verify that the method handles a valid product id that does not exist in catalog. | D61: ProductDetailService.findProductById(productId) | E61: productId = 'UNKNOWN_001'; mocked repository returns null | F61: Return ProductNotFound result or throw NotFoundException; no detail DTO is returned. | G61: Return ProductNotFound result | H61: pass | I61: Covers alternative flow: product not found.
A62: UT_VPD_006 | B62: canViewProductDetail - Customer Allowed | C62: Verify that a customer can view product detail without login, as customer login is not required. | D62: ProductDetailAccessChecker.canViewProductDetail(actor, product) | E62: actor = { role: 'Customer', isAuthenticated: false }; product exists | F62: Return TRUE / access allowed. | G62: TRUE | H62: pass | I62: Based on AIMS requirement that customers do not need login.
A63: UT_VPD_007 | B63: canViewProductDetail - Product Manager Unauthorized | C63: Verify that product manager detail access is rejected if the manager is not authenticated. | D63: ProductDetailAccessChecker.canViewProductDetail(actor, product) | E63: actor = { role: 'ProductManager', isAuthenticated: false }; product exists | F63: Return FALSE or Unauthorized/Forbidden result. | G63: FALSE | H63: pass | I63: Covers role/access rule for Product Manager.
A64: UT_VPD_008 | B64: getAvailabilityStatus - Active and In Stock | C64: Verify availability status for an active product with positive stock. | D64: ProductAvailabilityService.getAvailabilityStatus(status, stock, actor) | E64: status = 'ACTIVE'; stock = 12; actor.role = 'Customer' | F64: Return status 'Available' and canAddToCart = TRUE. | G64: Return status 'Available' and canAddToCart = TRUE | H64: pass | I64: Valid partition for purchasable product.
...
